<?xml version='1.0' encoding='utf-8'?>
<robot name="Refrigerator_a728186f2bb912572d8564c06b061019_0.0013412556701002402">
  <link name="link0">
    <inertial>
      <mass value="0" />
      <inertia ixx="0" ixy="0" ixz="0" iyy="0" iyz="0" izz="0" />
    </inertial>
  </link>
  <link name="link1">
    <inertial>
      <mass value="0" />
      <inertia ixx="0" ixy="0" ixz="0" iyy="0" iyz="0" izz="0" />
    </inertial>
  </link>
  <joint name="joint1" type="prismatic">
    <origin xyz="0 0 0" rpy="0 0 0" />
    <parent link="link0" />
    <child link="link1" />
    <axis xyz="1 0 0" />
    <limit lower="-1000" upper="1000" />
  </joint>
  <link name="link2">
    <inertial>
      <mass value="0" />
      <inertia ixx="0" ixy="0" ixz="0" iyy="0" iyz="0" izz="0" />
    </inertial>
  </link>
  <joint name="joint2" type="prismatic">
    <origin xyz="0 0 0" rpy="0 0 0" />
    <parent link="link1" />
    <child link="link2" />
    <axis xyz="0 1 0" />
    <limit lower="-1000" upper="1000" />
  </joint>
  <link name="link3">
    <inertial>
      <mass value="0" />
      <inertia ixx="0" ixy="0" ixz="0" iyy="0" iyz="0" izz="0" />
    </inertial>
  </link>
  <joint name="joint3" type="prismatic">
    <origin xyz="0 0 0" rpy="0 0 0" />
    <parent link="link2" />
    <child link="link3" />
    <axis xyz="0 0 1" />
    <limit lower="-1000" upper="1000" />
  </joint>
  <link name="link4">
    <inertial>
      <mass value="0" />
      <inertia ixx="0" ixy="0" ixz="0" iyy="0" iyz="0" izz="0" />
    </inertial>
  </link>
  <joint name="joint4" type="continuous">
    <origin xyz="0 0 0" rpy="0 0 0" />
    <parent link="link3" />
    <child link="link4" />
    <axis xyz="1 0 0" />
  </joint>
  <link name="link5">
    <inertial>
      <mass value="0" />
      <inertia ixx="0" ixy="0" ixz="0" iyy="0" iyz="0" izz="0" />
    </inertial>
  </link>
  <joint name="joint5" type="continuous">
    <origin xyz="0 0 0" rpy="0 0 0" />
    <parent link="link4" />
    <child link="link5" />
    <axis xyz="0 1 0" />
  </joint>
  <link name="link6">
    <contact>
      <lateral_friction value="1.0" />
    </contact>
    <inertial>
      <origin xyz="0 0 0" rpy="0 0 0" />
      <mass value="0.0211157635" />
      <inertia ixx="1.68735e-05" ixy="-2.08e-08" ixz="7.72e-08" iyy="1.72869e-05" iyz="-1.78e-08" izz="5.4716e-06" />
    </inertial>
    <visual>
      <origin xyz="0 0 0" rpy="0 0 0" />
      <geometry>
        <mesh filename="model.obj" scale="1 1 1" />
      </geometry>
      <material name="white">
        <color rgba="1 1 1 1" />
      </material>
    </visual>
    <collision>
      <origin xyz="0 0 0" rpy="0 0 0" />
      <geometry>
        <mesh filename="coacd_decomposed.obj" scale="1 1 1" />
      </geometry>
    </collision>
  </link>
  <joint name="joint6" type="continuous">
    <origin xyz="0 0 0" rpy="0 0 0" />
    <parent link="link5" />
    <child link="link6" />
    <axis xyz="0 0 1" />
  </joint>
</robot>